10:48:50<autoresign.pyw:85>[CRITICAL]Traceback (most recent call last):
  File "D:\anaconda3\lib\site-packages\urllib3\connectionpool.py", line 382, in _make_request
    self._validate_conn(conn)
  File "D:\anaconda3\lib\site-packages\urllib3\connectionpool.py", line 1010, in _validate_conn
    conn.connect()
  File "D:\anaconda3\lib\site-packages\urllib3\connection.py", line 411, in connect
    self.sock = ssl_wrap_socket(
  File "D:\anaconda3\lib\site-packages\urllib3\util\ssl_.py", line 428, in ssl_wrap_socket
    ssl_sock = _ssl_wrap_socket_impl(
  File "D:\anaconda3\lib\site-packages\urllib3\util\ssl_.py", line 472, in _ssl_wrap_socket_impl
    return ssl_context.wrap_socket(sock, server_hostname=server_hostname)
  File "D:\anaconda3\lib\ssl.py", line 500, in wrap_socket
    return self.sslsocket_class._create(
  File "D:\anaconda3\lib\ssl.py", line 1040, in _create
    self.do_handshake()
  File "D:\anaconda3\lib\ssl.py", line 1309, in do_handshake
    self._sslobj.do_handshake()
socket.timeout: _ssl.c:1108: The handshake operation timed out

During handling of the above exception, another exception occurred:

Traceback (most recent call last):
  File "D:\anaconda3\lib\site-packages\requests\adapters.py", line 439, in send
    resp = conn.urlopen(
  File "D:\anaconda3\lib\site-packages\urllib3\connectionpool.py", line 755, in urlopen
    retries = retries.increment(
  File "D:\anaconda3\lib\site-packages\urllib3\util\retry.py", line 532, in increment
    raise six.reraise(type(error), error, _stacktrace)
  File "D:\anaconda3\lib\site-packages\urllib3\packages\six.py", line 735, in reraise
    raise value
  File "D:\anaconda3\lib\site-packages\urllib3\connectionpool.py", line 699, in urlopen
    httplib_response = self._make_request(
  File "D:\anaconda3\lib\site-packages\urllib3\connectionpool.py", line 385, in _make_request
    self._raise_timeout(err=e, url=url, timeout_value=conn.timeout)
  File "D:\anaconda3\lib\site-packages\urllib3\connectionpool.py", line 336, in _raise_timeout
    raise ReadTimeoutError(
urllib3.exceptions.ReadTimeoutError: HTTPSConnectionPool(host='www.baidu.com', port=443): Read timed out. (read timeout=5)

During handling of the above exception, another exception occurred:

Traceback (most recent call last):
  File "C:\Users\csuxyh\Desktop\autoresign.pyw", line 82, in checkconnect
    r = requests.get('https://www.baidu.com', timeout=5)
  File "D:\anaconda3\lib\site-packages\requests\api.py", line 76, in get
    return request('get', url, params=params, **kwargs)
  File "D:\anaconda3\lib\site-packages\requests\api.py", line 61, in request
    return session.request(method=method, url=url, **kwargs)
  File "D:\anaconda3\lib\site-packages\requests\sessions.py", line 542, in request
    resp = self.send(prep, **send_kwargs)
  File "D:\anaconda3\lib\site-packages\requests\sessions.py", line 655, in send
    r = adapter.send(request, **kwargs)
  File "D:\anaconda3\lib\site-packages\requests\adapters.py", line 529, in send
    raise ReadTimeout(e, request=request)
requests.exceptions.ReadTimeout: HTTPSConnectionPool(host='www.baidu.com', port=443): Read timed out. (read timeout=5)

10:48:50<autoresign.pyw:77>[INFO]reconnect at 2021-10-23 10:48:50.125677
